2022-07-29 17:37:14,162 - app - ERROR - 登入成功
2022-07-29 17:41:16,681 - app - INFO - 登入成功
2022-07-29 17:46:08,889 - app - ERROR - Exception on /v1/user/login [POST]
Traceback (most recent call last):
  File "/Users/barin/works/venvs/flask_venv/lib/python3.8/site-packages/flask/app.py", line 1517, in full_dispatch_request
    rv = self.dispatch_request()
  File "/Users/barin/works/venvs/flask_venv/lib/python3.8/site-packages/flask/app.py", line 1503, in dispatch_request
    return self.ensure_sync(self.view_functions[rule.endpoint])(**req.view_args)
  File "/Users/barin/works/panel_app/api/user/user_login.py", line 18, in user_login
    user, token = UserControl._login(username.strip(), password.strip())
  File "/Users/barin/works/panel_app/control/v1/user.py", line 30, in _login
    cls._vali_password(password, user.us_salt, user.us_password)
  File "/Users/barin/works/panel_app/control/v1/user.py", line 42, in _vali_password
    make_error(ResponseCode.user_password)
  File "/Users/barin/works/panel_app/res/error.py", line 99, in make_error
    raise ResponseError(code.value, message)
res.error.ResponseError: (20104, '')

During handling of the above exception, another exception occurred:

Traceback (most recent call last):
  File "/Users/barin/works/venvs/flask_venv/lib/python3.8/site-packages/flask/app.py", line 2073, in wsgi_app
    response = self.full_dispatch_request()
  File "/Users/barin/works/venvs/flask_venv/lib/python3.8/site-packages/flask/app.py", line 1519, in full_dispatch_request
    rv = self.handle_user_exception(e)
  File "/Users/barin/works/venvs/flask_venv/lib/python3.8/site-packages/flask_cors/extension.py", line 165, in wrapped_function
    return cors_after_request(app.make_response(f(*args, **kwargs)))
  File "/Users/barin/works/venvs/flask_venv/lib/python3.8/site-packages/flask/app.py", line 1695, in make_response
    raise TypeError(
TypeError: The view function for 'user.user_login' did not return a valid response. The function either returned None or ended without a return statement.
2022-07-29 17:46:25,052 - app - ERROR - Exception on /v1/user/login [POST]
Traceback (most recent call last):
  File "/Users/barin/works/venvs/flask_venv/lib/python3.8/site-packages/flask/app.py", line 1517, in full_dispatch_request
    rv = self.dispatch_request()
  File "/Users/barin/works/venvs/flask_venv/lib/python3.8/site-packages/flask/app.py", line 1503, in dispatch_request
    return self.ensure_sync(self.view_functions[rule.endpoint])(**req.view_args)
  File "/Users/barin/works/panel_app/api/user/user_login.py", line 18, in user_login
    user, token = UserControl._login(username.strip(), password.strip())
  File "/Users/barin/works/panel_app/control/v1/user.py", line 30, in _login
    cls._vali_password(password, user.us_salt, user.us_password)
  File "/Users/barin/works/panel_app/control/v1/user.py", line 42, in _vali_password
    make_error(ResponseCode.user_password)
  File "/Users/barin/works/panel_app/res/error.py", line 99, in make_error
    raise ResponseError(code.value, message)
res.error.ResponseError: (20104, '')

During handling of the above exception, another exception occurred:

Traceback (most recent call last):
  File "/Users/barin/works/venvs/flask_venv/lib/python3.8/site-packages/flask/app.py", line 2073, in wsgi_app
    response = self.full_dispatch_request()
  File "/Users/barin/works/venvs/flask_venv/lib/python3.8/site-packages/flask/app.py", line 1519, in full_dispatch_request
    rv = self.handle_user_exception(e)
  File "/Users/barin/works/venvs/flask_venv/lib/python3.8/site-packages/flask_cors/extension.py", line 165, in wrapped_function
    return cors_after_request(app.make_response(f(*args, **kwargs)))
  File "/Users/barin/works/venvs/flask_venv/lib/python3.8/site-packages/flask/app.py", line 1695, in make_response
    raise TypeError(
TypeError: The view function for 'user.user_login' did not return a valid response. The function either returned None or ended without a return statement.
2022-07-29 17:48:01,884 - app - ERROR - Exception on /v1/user/login [POST]
Traceback (most recent call last):
  File "/Users/barin/works/venvs/flask_venv/lib/python3.8/site-packages/flask/app.py", line 1517, in full_dispatch_request
    rv = self.dispatch_request()
  File "/Users/barin/works/venvs/flask_venv/lib/python3.8/site-packages/flask/app.py", line 1503, in dispatch_request
    return self.ensure_sync(self.view_functions[rule.endpoint])(**req.view_args)
  File "/Users/barin/works/panel_app/api/user/user_login.py", line 18, in user_login
    user, token = UserControl._login(username.strip(), password.strip())
  File "/Users/barin/works/panel_app/control/v1/user.py", line 30, in _login
    cls._vali_password(password, user.us_salt, user.us_password)
  File "/Users/barin/works/panel_app/control/v1/user.py", line 42, in _vali_password
    make_error(ResponseCode.user_password)
  File "/Users/barin/works/panel_app/res/error.py", line 99, in make_error
    raise ResponseError(code.value, message)
res.error.ResponseError: (20104, '')

During handling of the above exception, another exception occurred:

Traceback (most recent call last):
  File "/Users/barin/works/venvs/flask_venv/lib/python3.8/site-packages/flask/app.py", line 2073, in wsgi_app
    response = self.full_dispatch_request()
  File "/Users/barin/works/venvs/flask_venv/lib/python3.8/site-packages/flask/app.py", line 1519, in full_dispatch_request
    rv = self.handle_user_exception(e)
  File "/Users/barin/works/venvs/flask_venv/lib/python3.8/site-packages/flask_cors/extension.py", line 165, in wrapped_function
    return cors_after_request(app.make_response(f(*args, **kwargs)))
  File "/Users/barin/works/venvs/flask_venv/lib/python3.8/site-packages/flask/app.py", line 1714, in make_response
    rv = jsonify(rv)
  File "/Users/barin/works/venvs/flask_venv/lib/python3.8/site-packages/flask/json/__init__.py", line 302, in jsonify
    f"{dumps(data, indent=indent, separators=separators)}\n",
  File "/Users/barin/works/venvs/flask_venv/lib/python3.8/site-packages/flask/json/__init__.py", line 132, in dumps
    return _json.dumps(obj, **kwargs)
  File "/Library/Developer/CommandLineTools/Library/Frameworks/Python3.framework/Versions/3.8/lib/python3.8/json/__init__.py", line 234, in dumps
    return cls(
  File "/Library/Developer/CommandLineTools/Library/Frameworks/Python3.framework/Versions/3.8/lib/python3.8/json/encoder.py", line 199, in encode
    chunks = self.iterencode(o, _one_shot=True)
  File "/Library/Developer/CommandLineTools/Library/Frameworks/Python3.framework/Versions/3.8/lib/python3.8/json/encoder.py", line 257, in iterencode
    return _iterencode(o, 0)
  File "/Users/barin/works/venvs/flask_venv/lib/python3.8/site-packages/flask/json/__init__.py", line 51, in default
    return super().default(o)
  File "/Library/Developer/CommandLineTools/Library/Frameworks/Python3.framework/Versions/3.8/lib/python3.8/json/encoder.py", line 179, in default
    raise TypeError(f'Object of type {o.__class__.__name__} '
TypeError: Object of type ResponseError is not JSON serializable
2022-07-29 17:48:02,939 - app - ERROR - Exception on /v1/user/login [POST]
Traceback (most recent call last):
  File "/Users/barin/works/venvs/flask_venv/lib/python3.8/site-packages/flask/app.py", line 1517, in full_dispatch_request
    rv = self.dispatch_request()
  File "/Users/barin/works/venvs/flask_venv/lib/python3.8/site-packages/flask/app.py", line 1503, in dispatch_request
    return self.ensure_sync(self.view_functions[rule.endpoint])(**req.view_args)
  File "/Users/barin/works/panel_app/api/user/user_login.py", line 18, in user_login
    user, token = UserControl._login(username.strip(), password.strip())
  File "/Users/barin/works/panel_app/control/v1/user.py", line 30, in _login
    cls._vali_password(password, user.us_salt, user.us_password)
  File "/Users/barin/works/panel_app/control/v1/user.py", line 42, in _vali_password
    make_error(ResponseCode.user_password)
  File "/Users/barin/works/panel_app/res/error.py", line 99, in make_error
    raise ResponseError(code.value, message)
res.error.ResponseError: (20104, '')

During handling of the above exception, another exception occurred:

Traceback (most recent call last):
  File "/Users/barin/works/venvs/flask_venv/lib/python3.8/site-packages/flask/app.py", line 2073, in wsgi_app
    response = self.full_dispatch_request()
  File "/Users/barin/works/venvs/flask_venv/lib/python3.8/site-packages/flask/app.py", line 1519, in full_dispatch_request
    rv = self.handle_user_exception(e)
  File "/Users/barin/works/venvs/flask_venv/lib/python3.8/site-packages/flask_cors/extension.py", line 165, in wrapped_function
    return cors_after_request(app.make_response(f(*args, **kwargs)))
  File "/Users/barin/works/venvs/flask_venv/lib/python3.8/site-packages/flask/app.py", line 1714, in make_response
    rv = jsonify(rv)
  File "/Users/barin/works/venvs/flask_venv/lib/python3.8/site-packages/flask/json/__init__.py", line 302, in jsonify
    f"{dumps(data, indent=indent, separators=separators)}\n",
  File "/Users/barin/works/venvs/flask_venv/lib/python3.8/site-packages/flask/json/__init__.py", line 132, in dumps
    return _json.dumps(obj, **kwargs)
  File "/Library/Developer/CommandLineTools/Library/Frameworks/Python3.framework/Versions/3.8/lib/python3.8/json/__init__.py", line 234, in dumps
    return cls(
  File "/Library/Developer/CommandLineTools/Library/Frameworks/Python3.framework/Versions/3.8/lib/python3.8/json/encoder.py", line 199, in encode
    chunks = self.iterencode(o, _one_shot=True)
  File "/Library/Developer/CommandLineTools/Library/Frameworks/Python3.framework/Versions/3.8/lib/python3.8/json/encoder.py", line 257, in iterencode
    return _iterencode(o, 0)
  File "/Users/barin/works/venvs/flask_venv/lib/python3.8/site-packages/flask/json/__init__.py", line 51, in default
    return super().default(o)
  File "/Library/Developer/CommandLineTools/Library/Frameworks/Python3.framework/Versions/3.8/lib/python3.8/json/encoder.py", line 179, in default
    raise TypeError(f'Object of type {o.__class__.__name__} '
TypeError: Object of type ResponseError is not JSON serializable
2022-07-29 17:49:24,441 - app - ERROR - Exception on /v1/user/login [POST]
Traceback (most recent call last):
  File "/Users/barin/works/venvs/flask_venv/lib/python3.8/site-packages/flask/app.py", line 1517, in full_dispatch_request
    rv = self.dispatch_request()
  File "/Users/barin/works/venvs/flask_venv/lib/python3.8/site-packages/flask/app.py", line 1503, in dispatch_request
    return self.ensure_sync(self.view_functions[rule.endpoint])(**req.view_args)
  File "/Users/barin/works/panel_app/api/user/user_login.py", line 18, in user_login
    user, token = UserControl._login(username.strip(), password.strip())
  File "/Users/barin/works/panel_app/control/v1/user.py", line 30, in _login
    cls._vali_password(password, user.us_salt, user.us_password)
  File "/Users/barin/works/panel_app/control/v1/user.py", line 42, in _vali_password
    make_error(ResponseCode.user_password)
  File "/Users/barin/works/panel_app/res/error.py", line 99, in make_error
    raise ResponseError(code.value, message)
res.error.ResponseError: (20104, '')

During handling of the above exception, another exception occurred:

Traceback (most recent call last):
  File "/Users/barin/works/venvs/flask_venv/lib/python3.8/site-packages/flask/app.py", line 2073, in wsgi_app
    response = self.full_dispatch_request()
  File "/Users/barin/works/venvs/flask_venv/lib/python3.8/site-packages/flask/app.py", line 1519, in full_dispatch_request
    rv = self.handle_user_exception(e)
  File "/Users/barin/works/venvs/flask_venv/lib/python3.8/site-packages/flask_cors/extension.py", line 165, in wrapped_function
    return cors_after_request(app.make_response(f(*args, **kwargs)))
  File "/Users/barin/works/venvs/flask_venv/lib/python3.8/site-packages/flask/app.py", line 1714, in make_response
    rv = jsonify(rv)
  File "/Users/barin/works/venvs/flask_venv/lib/python3.8/site-packages/flask/json/__init__.py", line 302, in jsonify
    f"{dumps(data, indent=indent, separators=separators)}\n",
  File "/Users/barin/works/venvs/flask_venv/lib/python3.8/site-packages/flask/json/__init__.py", line 132, in dumps
    return _json.dumps(obj, **kwargs)
  File "/Library/Developer/CommandLineTools/Library/Frameworks/Python3.framework/Versions/3.8/lib/python3.8/json/__init__.py", line 234, in dumps
    return cls(
  File "/Library/Developer/CommandLineTools/Library/Frameworks/Python3.framework/Versions/3.8/lib/python3.8/json/encoder.py", line 199, in encode
    chunks = self.iterencode(o, _one_shot=True)
  File "/Library/Developer/CommandLineTools/Library/Frameworks/Python3.framework/Versions/3.8/lib/python3.8/json/encoder.py", line 257, in iterencode
    return _iterencode(o, 0)
  File "/Users/barin/works/venvs/flask_venv/lib/python3.8/site-packages/flask/json/__init__.py", line 51, in default
    return super().default(o)
  File "/Library/Developer/CommandLineTools/Library/Frameworks/Python3.framework/Versions/3.8/lib/python3.8/json/encoder.py", line 179, in default
    raise TypeError(f'Object of type {o.__class__.__name__} '
TypeError: Object of type ResponseError is not JSON serializable
2022-07-29 17:51:50,238 - app - ERROR - Exception on /v1/user/login [POST]
Traceback (most recent call last):
  File "/Users/barin/works/venvs/flask_venv/lib/python3.8/site-packages/flask/app.py", line 1517, in full_dispatch_request
    rv = self.dispatch_request()
  File "/Users/barin/works/venvs/flask_venv/lib/python3.8/site-packages/flask/app.py", line 1503, in dispatch_request
    return self.ensure_sync(self.view_functions[rule.endpoint])(**req.view_args)
  File "/Users/barin/works/panel_app/api/user/user_login.py", line 18, in user_login
    user, token = UserControl._login(username.strip(), password.strip())
  File "/Users/barin/works/panel_app/control/v1/user.py", line 30, in _login
    cls._vali_password(password, user.us_salt, user.us_password)
  File "/Users/barin/works/panel_app/control/v1/user.py", line 42, in _vali_password
    make_error(ResponseCode.user_password)
  File "/Users/barin/works/panel_app/res/error.py", line 99, in make_error
    raise ResponseError(code.value, message)
res.error.ResponseError: (20104, '')

During handling of the above exception, another exception occurred:

Traceback (most recent call last):
  File "/Users/barin/works/venvs/flask_venv/lib/python3.8/site-packages/flask/app.py", line 2073, in wsgi_app
    response = self.full_dispatch_request()
  File "/Users/barin/works/venvs/flask_venv/lib/python3.8/site-packages/flask/app.py", line 1519, in full_dispatch_request
    rv = self.handle_user_exception(e)
  File "/Users/barin/works/venvs/flask_venv/lib/python3.8/site-packages/flask_cors/extension.py", line 165, in wrapped_function
    return cors_after_request(app.make_response(f(*args, **kwargs)))
  File "/Users/barin/works/venvs/flask_venv/lib/python3.8/site-packages/flask/app.py", line 1385, in handle_user_exception
    return self.ensure_sync(handler)(e)
  File "/Users/barin/works/panel_app/app.py", line 45, in internal_server_error
    return {"code": -1, "message": jsonify(e)}
  File "/Users/barin/works/venvs/flask_venv/lib/python3.8/site-packages/flask/json/__init__.py", line 302, in jsonify
    f"{dumps(data, indent=indent, separators=separators)}\n",
  File "/Users/barin/works/venvs/flask_venv/lib/python3.8/site-packages/flask/json/__init__.py", line 132, in dumps
    return _json.dumps(obj, **kwargs)
  File "/Library/Developer/CommandLineTools/Library/Frameworks/Python3.framework/Versions/3.8/lib/python3.8/json/__init__.py", line 234, in dumps
    return cls(
  File "/Library/Developer/CommandLineTools/Library/Frameworks/Python3.framework/Versions/3.8/lib/python3.8/json/encoder.py", line 199, in encode
    chunks = self.iterencode(o, _one_shot=True)
  File "/Library/Developer/CommandLineTools/Library/Frameworks/Python3.framework/Versions/3.8/lib/python3.8/json/encoder.py", line 257, in iterencode
    return _iterencode(o, 0)
  File "/Users/barin/works/venvs/flask_venv/lib/python3.8/site-packages/flask/json/__init__.py", line 51, in default
    return super().default(o)
  File "/Library/Developer/CommandLineTools/Library/Frameworks/Python3.framework/Versions/3.8/lib/python3.8/json/encoder.py", line 179, in default
    raise TypeError(f'Object of type {o.__class__.__name__} '
TypeError: Object of type ResponseError is not JSON serializable
2022-07-29 17:52:28,153 - app - ERROR - Exception on /v1/user/login [POST]
Traceback (most recent call last):
  File "/Users/barin/works/venvs/flask_venv/lib/python3.8/site-packages/flask/app.py", line 1517, in full_dispatch_request
    rv = self.dispatch_request()
  File "/Users/barin/works/venvs/flask_venv/lib/python3.8/site-packages/flask/app.py", line 1503, in dispatch_request
    return self.ensure_sync(self.view_functions[rule.endpoint])(**req.view_args)
  File "/Users/barin/works/panel_app/api/user/user_login.py", line 18, in user_login
    user, token = UserControl._login(username.strip(), password.strip())
  File "/Users/barin/works/panel_app/control/v1/user.py", line 30, in _login
    cls._vali_password(password, user.us_salt, user.us_password)
  File "/Users/barin/works/panel_app/control/v1/user.py", line 42, in _vali_password
    make_error(ResponseCode.user_password)
  File "/Users/barin/works/panel_app/res/error.py", line 99, in make_error
    raise ResponseError(code.value, message)
res.error.ResponseError: (20104, '')

During handling of the above exception, another exception occurred:

Traceback (most recent call last):
  File "/Users/barin/works/venvs/flask_venv/lib/python3.8/site-packages/flask/app.py", line 2073, in wsgi_app
    response = self.full_dispatch_request()
  File "/Users/barin/works/venvs/flask_venv/lib/python3.8/site-packages/flask/app.py", line 1519, in full_dispatch_request
    rv = self.handle_user_exception(e)
  File "/Users/barin/works/venvs/flask_venv/lib/python3.8/site-packages/flask_cors/extension.py", line 165, in wrapped_function
    return cors_after_request(app.make_response(f(*args, **kwargs)))
  File "/Users/barin/works/venvs/flask_venv/lib/python3.8/site-packages/flask/app.py", line 1385, in handle_user_exception
    return self.ensure_sync(handler)(e)
  File "/Users/barin/works/panel_app/app.py", line 45, in internal_server_error
    return jsonify({"code": -1, "message": e})
  File "/Users/barin/works/venvs/flask_venv/lib/python3.8/site-packages/flask/json/__init__.py", line 302, in jsonify
    f"{dumps(data, indent=indent, separators=separators)}\n",
  File "/Users/barin/works/venvs/flask_venv/lib/python3.8/site-packages/flask/json/__init__.py", line 132, in dumps
    return _json.dumps(obj, **kwargs)
  File "/Library/Developer/CommandLineTools/Library/Frameworks/Python3.framework/Versions/3.8/lib/python3.8/json/__init__.py", line 234, in dumps
    return cls(
  File "/Library/Developer/CommandLineTools/Library/Frameworks/Python3.framework/Versions/3.8/lib/python3.8/json/encoder.py", line 199, in encode
    chunks = self.iterencode(o, _one_shot=True)
  File "/Library/Developer/CommandLineTools/Library/Frameworks/Python3.framework/Versions/3.8/lib/python3.8/json/encoder.py", line 257, in iterencode
    return _iterencode(o, 0)
  File "/Users/barin/works/venvs/flask_venv/lib/python3.8/site-packages/flask/json/__init__.py", line 51, in default
    return super().default(o)
  File "/Library/Developer/CommandLineTools/Library/Frameworks/Python3.framework/Versions/3.8/lib/python3.8/json/encoder.py", line 179, in default
    raise TypeError(f'Object of type {o.__class__.__name__} '
TypeError: Object of type ResponseError is not JSON serializable
2022-07-29 17:58:15,471 - app - ERROR - Exception on /v1/user/register [POST]
Traceback (most recent call last):
  File "/Users/barin/works/venvs/flask_venv/lib/python3.8/site-packages/flask/app.py", line 1517, in full_dispatch_request
    rv = self.dispatch_request()
  File "/Users/barin/works/venvs/flask_venv/lib/python3.8/site-packages/flask/app.py", line 1503, in dispatch_request
    return self.ensure_sync(self.view_functions[rule.endpoint])(**req.view_args)
  File "/Users/barin/works/panel_app/api/user/user_register.py", line 17, in user_register
    if not UserControl._register(username, password):
  File "/Users/barin/works/panel_app/control/v1/user.py", line 79, in _register
    make_error(ResponseCode.user_existed)
  File "/Users/barin/works/panel_app/res/error.py", line 99, in make_error
    raise ResponseError(code.value, message)
res.error.ResponseError: (20103, 'User is existed')

During handling of the above exception, another exception occurred:

Traceback (most recent call last):
  File "/Users/barin/works/venvs/flask_venv/lib/python3.8/site-packages/flask/app.py", line 2073, in wsgi_app
    response = self.full_dispatch_request()
  File "/Users/barin/works/venvs/flask_venv/lib/python3.8/site-packages/flask/app.py", line 1519, in full_dispatch_request
    rv = self.handle_user_exception(e)
  File "/Users/barin/works/venvs/flask_venv/lib/python3.8/site-packages/flask_cors/extension.py", line 165, in wrapped_function
    return cors_after_request(app.make_response(f(*args, **kwargs)))
  File "/Users/barin/works/venvs/flask_venv/lib/python3.8/site-packages/flask/app.py", line 1385, in handle_user_exception
    return self.ensure_sync(handler)(e)
  File "/Users/barin/works/panel_app/app.py", line 45, in internal_server_error
    return jsonify({"code": -1, "message": e})
  File "/Users/barin/works/venvs/flask_venv/lib/python3.8/site-packages/flask/json/__init__.py", line 302, in jsonify
    f"{dumps(data, indent=indent, separators=separators)}\n",
  File "/Users/barin/works/venvs/flask_venv/lib/python3.8/site-packages/flask/json/__init__.py", line 132, in dumps
    return _json.dumps(obj, **kwargs)
  File "/Library/Developer/CommandLineTools/Library/Frameworks/Python3.framework/Versions/3.8/lib/python3.8/json/__init__.py", line 234, in dumps
    return cls(
  File "/Library/Developer/CommandLineTools/Library/Frameworks/Python3.framework/Versions/3.8/lib/python3.8/json/encoder.py", line 199, in encode
    chunks = self.iterencode(o, _one_shot=True)
  File "/Library/Developer/CommandLineTools/Library/Frameworks/Python3.framework/Versions/3.8/lib/python3.8/json/encoder.py", line 257, in iterencode
    return _iterencode(o, 0)
  File "/Users/barin/works/venvs/flask_venv/lib/python3.8/site-packages/flask/json/__init__.py", line 51, in default
    return super().default(o)
  File "/Library/Developer/CommandLineTools/Library/Frameworks/Python3.framework/Versions/3.8/lib/python3.8/json/encoder.py", line 179, in default
    raise TypeError(f'Object of type {o.__class__.__name__} '
TypeError: Object of type ResponseError is not JSON serializable
2022-07-29 17:58:30,033 - app - ERROR - Exception on /v1/user/register [POST]
Traceback (most recent call last):
  File "/Users/barin/works/venvs/flask_venv/lib/python3.8/site-packages/flask/app.py", line 2073, in wsgi_app
    response = self.full_dispatch_request()
  File "/Users/barin/works/venvs/flask_venv/lib/python3.8/site-packages/flask/app.py", line 1519, in full_dispatch_request
    rv = self.handle_user_exception(e)
  File "/Users/barin/works/venvs/flask_venv/lib/python3.8/site-packages/flask_cors/extension.py", line 165, in wrapped_function
    return cors_after_request(app.make_response(f(*args, **kwargs)))
  File "/Users/barin/works/venvs/flask_venv/lib/python3.8/site-packages/flask/app.py", line 1517, in full_dispatch_request
    rv = self.dispatch_request()
  File "/Users/barin/works/venvs/flask_venv/lib/python3.8/site-packages/flask/app.py", line 1503, in dispatch_request
    return self.ensure_sync(self.view_functions[rule.endpoint])(**req.view_args)
  File "/Users/barin/works/panel_app/api/user/user_register.py", line 17, in user_register
    if not UserControl._register(username, password):
  File "/Users/barin/works/panel_app/control/v1/user.py", line 79, in _register
    make_error(ResponseCode.user_existed)
  File "/Users/barin/works/panel_app/res/error.py", line 99, in make_error
    raise ResponseError(code.value, message)
res.error.ResponseError: (20103, 'User is existed')
2022-07-29 18:04:30,147 - app - ERROR - Exception on /v1/user/logout [GET]
Traceback (most recent call last):
  File "/Users/barin/works/venvs/flask_venv/lib/python3.8/site-packages/flask/app.py", line 2073, in wsgi_app
    response = self.full_dispatch_request()
  File "/Users/barin/works/venvs/flask_venv/lib/python3.8/site-packages/flask/app.py", line 1519, in full_dispatch_request
    rv = self.handle_user_exception(e)
  File "/Users/barin/works/venvs/flask_venv/lib/python3.8/site-packages/flask_cors/extension.py", line 165, in wrapped_function
    return cors_after_request(app.make_response(f(*args, **kwargs)))
  File "/Users/barin/works/venvs/flask_venv/lib/python3.8/site-packages/flask/app.py", line 1517, in full_dispatch_request
    rv = self.dispatch_request()
  File "/Users/barin/works/venvs/flask_venv/lib/python3.8/site-packages/flask/app.py", line 1503, in dispatch_request
    return self.ensure_sync(self.view_functions[rule.endpoint])(**req.view_args)
  File "/Users/barin/works/panel_app/decorator/token.py", line 39, in wrapper
    make_error(ResponseCode.token_illegal)
  File "/Users/barin/works/panel_app/res/error.py", line 99, in make_error
    raise ResponseError(code.value, message)
res.error.ResponseError: (20204, 'Token illegal')
2022-07-29 18:04:51,066 - app - INFO - token 检测成功
2022-07-29 18:04:51,073 - app - ERROR - Exception on /v1/user/logout [GET]
Traceback (most recent call last):
  File "/Users/barin/works/venvs/flask_venv/lib/python3.8/site-packages/flask/app.py", line 2073, in wsgi_app
    response = self.full_dispatch_request()
  File "/Users/barin/works/venvs/flask_venv/lib/python3.8/site-packages/flask/app.py", line 1519, in full_dispatch_request
    rv = self.handle_user_exception(e)
  File "/Users/barin/works/venvs/flask_venv/lib/python3.8/site-packages/flask_cors/extension.py", line 165, in wrapped_function
    return cors_after_request(app.make_response(f(*args, **kwargs)))
  File "/Users/barin/works/venvs/flask_venv/lib/python3.8/site-packages/flask/app.py", line 1517, in full_dispatch_request
    rv = self.dispatch_request()
  File "/Users/barin/works/venvs/flask_venv/lib/python3.8/site-packages/flask/app.py", line 1503, in dispatch_request
    return self.ensure_sync(self.view_functions[rule.endpoint])(**req.view_args)
  File "/Users/barin/works/panel_app/decorator/token.py", line 54, in wrapper
    return func(*a, **b)
  File "/Users/barin/works/panel_app/api/user/user_logout.py", line 22, in user_logout
    UserControl._logout(token)
  File "/Users/barin/works/panel_app/control/v1/user.py", line 105, in _logout
    make_error(ResponseCode.token_illegal)
  File "/Users/barin/works/panel_app/res/error.py", line 99, in make_error
    raise ResponseError(code.value, message)
res.error.ResponseError: (20204, 'Token illegal')
